Workbook

Sheet Chungwoon University(Hongseong)
A1: University | B1: Major | C1: English Medium | D1: Korean Medium | E1: Degree Type | F1: Tuition Fee (KRW) | G1: Tuition Fee (LKR) | H1: Dorm Double (KRW) | I1: Dorm Double (LKR) | J1: Dorm Single (KRW) | K1: Dorm Single (LKR) | L1: Total with Dorm Double (LKR) | M1: Total with Dorm Single (LKR)
A2: Chungwoon University | B2: Acting | C2: No | D2: Yes | E2: Bachelor | F2: 4052500 | G2: =IFERROR(ROUND(F2*0.21,0),"") -> 851025 | H2: 1250000 | I2: =IFERROR(ROUND(H2*0.21,0),"") -> 262500 | J2: 1500000 | K2: =IFERROR(ROUND(J2*0.21,0),"") -> 315000 | L2: =IF(OR(G2="",I2=""),"",G2+I2) -> 1113525 | M2: =IF(OR(G2="",K2=""),"",G2+K2) -> 1166025
A3: Chungwoon University | B3: Musical | C3: No | D3: Yes | E3: Bachelor | F3: 4360500 | G3: =IFERROR(ROUND(F3*0.21,0),"") -> 915705 | H3: 1250000 | I3: =IFERROR(ROUND(H3*0.21,0),"") -> 262500 | J3: 1500000 | K3: =IFERROR(ROUND(J3*0.21,0),"") -> 315000 | L3: =IF(OR(G3="",I3=""),"",G3+I3) -> 1178205 | M3: =IF(OR(G3="",K3=""),"",G3+K3) -> 1230705
A4: Chungwoon University | B4: Music Trainer (Instrumental) | C4: No | D4: Yes | E4: Bachelor | F4: 4360500 | G4: =IFERROR(ROUND(F4*0.21,0),"") -> 915705 | H4: 1250000 | I4: =IFERROR(ROUND(H4*0.21,0),"") -> 262500 | J4: 1500000 | K4: =IFERROR(ROUND(J4*0.21,0),"") -> 315000 | L4: =IF(OR(G4="",I4=""),"",G4+I4) -> 1178205 | M4: =IF(OR(G4="",K4=""),"",G4+K4) -> 1230705
A5: Chungwoon University | B5: Music Trainer (Vocal/Rap) | C5: No | D5: Yes | E5: Bachelor | F5: 4360500 | G5: =IFERROR(ROUND(F5*0.21,0),"") -> 915705 | H5: 1250000 | I5: =IFERROR(ROUND(H5*0.21,0),"") -> 262500 | J5: 1500000 | K5: =IFERROR(ROUND(J5*0.21,0),"") -> 315000 | L5: =IF(OR(G5="",I5=""),"",G5+I5) -> 1178205 | M5: =IF(OR(G5="",K5=""),"",G5+K5) -> 1230705
A6: Chungwoon University | B6: Music Trainer (MIDI / Computer Music) | C6: No | D6: Yes | E6: Bachelor | F6: 4360500 | G6: =IFERROR(ROUND(F6*0.21,0),"") -> 915705 | H6: 1250000 | I6: =IFERROR(ROUND(H6*0.21,0),"") -> 262500 | J6: 1500000 | K6: =IFERROR(ROUND(J6*0.21,0),"") -> 315000 | L6: =IF(OR(G6="",I6=""),"",G6+I6) -> 1178205 | M6: =IF(OR(G6="",K6=""),"",G6+K6) -> 1230705
A7: Chungwoon University | B7: Performing Arts Planning & Management | C7: No | D7: Yes | E7: Bachelor | F7: 4001000 | G7: =IFERROR(ROUND(F7*0.21,0),"") -> 840210 | H7: 1250000 | I7: =IFERROR(ROUND(H7*0.21,0),"") -> 262500 | J7: 1500000 | K7: =IFERROR(ROUND(J7*0.21,0),"") -> 315000 | L7: =IF(OR(G7="",I7=""),"",G7+I7) -> 1102710 | M7: =IF(OR(G7="",K7=""),"",G7+K7) -> 1155210
A8: Chungwoon University | B8: Broadcasting & Film | C8: No | D8: Yes | E8: Bachelor | F8: 4001000 | G8: =IFERROR(ROUND(F8*0.21,0),"") -> 840210 | H8: 1250000 | I8: =IFERROR(ROUND(H8*0.21,0),"") -> 262500 | J8: 1500000 | K8: =IFERROR(ROUND(J8*0.21,0),"") -> 315000 | L8: =IF(OR(G8="",I8=""),"",G8+I8) -> 1102710 | M8: =IF(OR(G8="",K8=""),"",G8+K8) -> 1155210
A9: Chungwoon University | B9: Media Communication | C9: No | D9: Yes | E9: Bachelor | F9: 4001000 | G9: =IFERROR(ROUND(F9*0.21,0),"") -> 840210 | H9: 1250000 | I9: =IFERROR(ROUND(H9*0.21,0),"") -> 262500 | J9: 1500000 | K9: =IFERROR(ROUND(J9*0.21,0),"") -> 315000 | L9: =IF(OR(G9="",I9=""),"",G9+I9) -> 1102710 | M9: =IF(OR(G9="",K9=""),"",G9+K9) -> 1155210
A10: Chungwoon University | B10: Hotel Tourism Management | C10: No | D10: Yes | E10: Bachelor | G10: =IFERROR(ROUND(F10*0.21,0),"") -> 0 | H10: 1250000 | I10: =IFERROR(ROUND(H10*0.21,0),"") -> 262500 | J10: 1500000 | K10: =IFERROR(ROUND(J10*0.21,0),"") -> 315000 | L10: =IF(OR(G10="",I10=""),"",G10+I10) -> 262500 | M10: =IF(OR(G10="",K10=""),"",G10+K10) -> 315000
A11: Chungwoon University | B11: Hotel Culinary & Catering Management | C11: No | D11: Yes | E11: Bachelor | F11: 4001000 | G11: =IFERROR(ROUND(F11*0.21,0),"") -> 840210 | H11: 1250000 | I11: =IFERROR(ROUND(H11*0.21,0),"") -> 262500 | J11: 1500000 | K11: =IFERROR(ROUND(J11*0.21,0),"") -> 315000 | L11: =IF(OR(G11="",I11=""),"",G11+I11) -> 1102710 | M11: =IF(OR(G11="",K11=""),"",G11+K11) -> 1155210
A12: Chungwoon University | B12: Airline Service Management | C12: No | D12: Yes | E12: Bachelor | F12: 4001000 | G12: =IFERROR(ROUND(F12*0.21,0),"") -> 840210 | H12: 1250000 | I12: =IFERROR(ROUND(H12*0.21,0),"") -> 262500 | J12: 1500000 | K12: =IFERROR(ROUND(J12*0.21,0),"") -> 315000 | L12: =IF(OR(G12="",I12=""),"",G12+I12) -> 1102710 | M12: =IF(OR(G12="",K12=""),"",G12+K12) -> 1155210
A13: Chungwoon University | B13: Space Design | C13: No | D13: Yes | E13: Bachelor | F13: 4001000 | G13: =IFERROR(ROUND(F13*0.21,0),"") -> 840210 | H13: 1250000 | I13: =IFERROR(ROUND(H13*0.21,0),"") -> 262500 | J13: 1500000 | K13: =IFERROR(ROUND(J13*0.21,0),"") -> 315000 | L13: =IF(OR(G13="",I13=""),"",G13+I13) -> 1102710 | M13: =IF(OR(G13="",K13=""),"",G13+K13) -> 1155210
A14: Chungwoon University | B14: Fashion Design | C14: No | D14: Yes | E14: Bachelor | F14: 4001000 | G14: =IFERROR(ROUND(F14*0.21,0),"") -> 840210 | H14: 1250000 | I14: =IFERROR(ROUND(H14*0.21,0),"") -> 262500 | J14: 1500000 | K14: =IFERROR(ROUND(J14*0.21,0),"") -> 315000 | L14: =IF(OR(G14="",I14=""),"",G14+I14) -> 1102710 | M14: =IF(OR(G14="",K14=""),"",G14+K14) -> 1155210
A15: Chungwoon University | B15: Liberal Studies | C15: No | D15: Yes | E15: Bachelor | G15: =IFERROR(ROUND(F15*0.21,0),"") -> 0 | H15: 1250000 | I15: =IFERROR(ROUND(H15*0.21,0),"") -> 262500 | J15: 1500000 | K15: =IFERROR(ROUND(J15*0.21,0),"") -> 315000 | L15: =IF(OR(G15="",I15=""),"",G15+I15) -> 262500 | M15: =IF(OR(G15="",K15=""),"",G15+K15) -> 315000
A16: Chungwoon University | B16: Sports Science | C16: No | D16: Yes | E16: Bachelor | F16: 4001000 | G16: =IFERROR(ROUND(F16*0.21,0),"") -> 840210 | H16: 1250000 | I16: =IFERROR(ROUND(H16*0.21,0),"") -> 262500 | J16: 1500000 | K16: =IFERROR(ROUND(J16*0.21,0),"") -> 315000 | L16: =IF(OR(G16="",I16=""),"",G16+I16) -> 1102710 | M16: =IF(OR(G16="",K16=""),"",G16+K16) -> 1155210
A17: Chungwoon University | B17: Human Nutrition & Food Science | C17: No | D17: Yes | E17: Bachelor | F17: 4001000 | G17: =IFERROR(ROUND(F17*0.21,0),"") -> 840210 | H17: 1250000 | I17: =IFERROR(ROUND(H17*0.21,0),"") -> 262500 | J17: 1500000 | K17: =IFERROR(ROUND(J17*0.21,0),"") -> 315000 | L17: =IF(OR(G17="",I17=""),"",G17+I17) -> 1102710 | M17: =IF(OR(G17="",K17=""),"",G17+K17) -> 1155210
A18: Chungwoon University | B18: Social Welfare | C18: No | D18: Yes | E18: Bachelor | F18: 3310500 | G18: =IFERROR(ROUND(F18*0.21,0),"") -> 695205 | H18: 1250000 | I18: =IFERROR(ROUND(H18*0.21,0),"") -> 262500 | J18: 1500000 | K18: =IFERROR(ROUND(J18*0.21,0),"") -> 315000 | L18: =IF(OR(G18="",I18=""),"",G18+I18) -> 957705 | M18: =IF(OR(G18="",K18=""),"",G18+K18) -> 1010205
A19: Chungwoon University | B19: Architectural Engineering | C19: No | D19: Yes | E19: Bachelor | F19: 4001000 | G19: =IFERROR(ROUND(F19*0.21,0),"") -> 840210 | H19: 1250000 | I19: =IFERROR(ROUND(H19*0.21,0),"") -> 262500 | J19: 1500000 | K19: =IFERROR(ROUND(J19*0.21,0),"") -> 315000 | L19: =IF(OR(G19="",I19=""),"",G19+I19) -> 1102710 | M19: =IF(OR(G19="",K19=""),"",G19+K19) -> 1155210
A20: Chungwoon University | B20: Building Services Engineering & Fire Protection Systems | C20: No | D20: Yes | E20: Bachelor | F20: 4001000 | G20: =IFERROR(ROUND(F20*0.21,0),"") -> 840210 | H20: 1250000 | I20: =IFERROR(ROUND(H20*0.21,0),"") -> 262500 | J20: 1500000 | K20: =IFERROR(ROUND(J20*0.21,0),"") -> 315000 | L20: =IF(OR(G20="",I20=""),"",G20+I20) -> 1102710 | M20: =IF(OR(G20="",K20=""),"",G20+K20) -> 1155210
A21: Chungwoon University | B21: Civil & Environmental Engineering | C21: No | D21: Yes | E21: Bachelor | F21: 4001000 | G21: =IFERROR(ROUND(F21*0.21,0),"") -> 840210 | H21: 1250000 | I21: =IFERROR(ROUND(H21*0.21,0),"") -> 262500 | J21: 1500000 | K21: =IFERROR(ROUND(J21*0.21,0),"") -> 315000 | L21: =IF(OR(G21="",I21=""),"",G21+I21) -> 1102710 | M21: =IF(OR(G21="",K21=""),"",G21+K21) -> 1155210
A22: Chungwoon University | B22: Electronics Engineering | C22: No | D22: Yes | E22: Bachelor | F22: 4001000 | G22: =IFERROR(ROUND(F22*0.21,0),"") -> 840210 | H22: 1250000 | I22: =IFERROR(ROUND(H22*0.21,0),"") -> 262500 | J22: 1500000 | K22: =IFERROR(ROUND(J22*0.21,0),"") -> 315000 | L22: =IF(OR(G22="",I22=""),"",G22+I22) -> 1102710 | M22: =IF(OR(G22="",K22=""),"",G22+K22) -> 1155210
A23: Chungwoon University | B23: Computer Engineering | C23: No | D23: Yes | E23: Bachelor | F23: 4001000 | G23: =IFERROR(ROUND(F23*0.21,0),"") -> 840210 | H23: 1250000 | I23: =IFERROR(ROUND(H23*0.21,0),"") -> 262500 | J23: 1500000 | K23: =IFERROR(ROUND(J23*0.21,0),"") -> 315000 | L23: =IF(OR(G23="",I23=""),"",G23+I23) -> 1102710 | M23: =IF(OR(G23="",K23=""),"",G23+K23) -> 1155210
A24: Chungwoon University | B24: Multimedia Science | C24: No | D24: Yes | E24: Bachelor | F24: 4001000 | G24: =IFERROR(ROUND(F24*0.21,0),"") -> 840210 | H24: 1250000 | I24: =IFERROR(ROUND(H24*0.21,0),"") -> 262500 | J24: 1500000 | K24: =IFERROR(ROUND(J24*0.21,0),"") -> 315000 | L24: =IF(OR(G24="",I24=""),"",G24+I24) -> 1102710 | M24: =IF(OR(G24="",K24=""),"",G24+K24) -> 1155210
A25: Chungwoon University | B25: Chemical Engineering | C25: No | D25: Yes | E25: Bachelor | F25: 4001000 | G25: =IFERROR(ROUND(F25*0.21,0),"") -> 840210 | H25: 1250000 | I25: =IFERROR(ROUND(H25*0.21,0),"") -> 262500 | J25: 1500000 | K25: =IFERROR(ROUND(J25*0.21,0),"") -> 315000 | L25: =IF(OR(G25="",I25=""),"",G25+I25) -> 1102710 | M25: =IF(OR(G25="",K25=""),"",G25+K25) -> 1155210
A26: Chungwoon University | B26: Business Administration | C26: No | D26: Yes | E26: Bachelor | F26: 3310500 | G26: =IFERROR(ROUND(F26*0.21,0),"") -> 695205 | H26: 1250000 | I26: =IFERROR(ROUND(H26*0.21,0),"") -> 262500 | J26: 1500000 | K26: =IFERROR(ROUND(J26*0.21,0),"") -> 315000 | L26: =IF(OR(G26="",I26=""),"",G26+I26) -> 957705 | M26: =IF(OR(G26="",K26=""),"",G26+K26) -> 1010205
A27: Chungwoon University | B27: Global Trade & Logistics | C27: No | D27: Yes | E27: Bachelor | F27: 3310500 | G27: =IFERROR(ROUND(F27*0.21,0),"") -> 695205 | H27: 1250000 | I27: =IFERROR(ROUND(H27*0.21,0),"") -> 262500 | J27: 1500000 | K27: =IFERROR(ROUND(J27*0.21,0),"") -> 315000 | L27: =IF(OR(G27="",I27=""),"",G27+I27) -> 957705 | M27: =IF(OR(G27="",K27=""),"",G27+K27) -> 1010205
... A32: Chungwoon University | B32: Global Korean Studies | C32: No | D32: Yes | E32: Bachelor | F32: 4200000 | G32: =IFERROR(ROUND(F32*0.21,0),"") -> 882000 | H32: 1250000 | I32: =IFERROR(ROUND(H32*0.21,0),"") -> 262500 | J32: 1500000 | K32: =IFERROR(ROUND(J32*0.21,0),"") -> 315000 | L32: =IF(OR(G32="",I32=""),"",G32+I32) -> 1144500 | M32: =IF(OR(G32="",K32=""),"",G32+K32) -> 1197000
A33: Chungwoon University | B33: Department of Service Management | C33: Yes | D33: No | E33: Bachelor | G33: =IFERROR(ROUND(F33*0.21,0),"") -> 0 | H33: 1250000 | I33: =IFERROR(ROUND(H33*0.21,0),"") -> 262500 | J33: 1500000 | K33: =IFERROR(ROUND(J33*0.21,0),"") -> 315000 | L33: =IF(OR(G33="",I33=""),"",G33+I33) -> 262500 | M33: =IF(OR(G33="",K33=""),"",G33+K33) -> 315000
A34: Chungwoon University | B34: Social e-Business Entrepreneurship Department | C34: No | D34: Yes | E34: Master | F34: 3267000 | G34: =IFERROR(ROUND(F34*0.21,0),"") -> 686070 | H34: 1250000 | I34: =IFERROR(ROUND(H34*0.21,0),"") -> 262500 | J34: 1500000 | K34: =IFERROR(ROUND(J34*0.21,0),"") -> 315000 | L34: =IF(OR(G34="",I34=""),"",G34+I34) -> 948570 | M34: =IF(OR(G34="",K34=""),"",G34+K34) -> 1001070
A35: Chungwoon University | B35: Performing Arts | C35: No | D35: Yes | E35: Master | F35: 3636000 | G35: =IFERROR(ROUND(F35*0.21,0),"") -> 763560 | H35: 1250000 | I35: =IFERROR(ROUND(H35*0.21,0),"") -> 262500 | J35: 1500000 | K35: =IFERROR(ROUND(J35*0.21,0),"") -> 315000 | L35: =IF(OR(G35="",I35=""),"",G35+I35) -> 1026060 | M35: =IF(OR(G35="",K35=""),"",G35+K35) -> 1078560
A36: Chungwoon University | B36: Broadcasting & Film | C36: No | D36: Yes | E36: Master | F36: 3636000 | G36: =IFERROR(ROUND(F36*0.21,0),"") -> 763560 | H36: 1250000 | I36: =IFERROR(ROUND(H36*0.21,0),"") -> 262500 | J36: 1500000 | K36: =IFERROR(ROUND(J36*0.21,0),"") -> 315000 | L36: =IF(OR(G36="",I36=""),"",G36+I36) -> 1026060 | M36: =IF(OR(G36="",K36=""),"",G36+K36) -> 1078560
A37: Chungwoon University | B37: Media Communication | C37: No | D37: Yes | E37: Master | F37: 3636000 | G37: =IFERROR(ROUND(F37*0.21,0),"") -> 763560 | H37: 1250000 | I37: =IFERROR(ROUND(H37*0.21,0),"") -> 262500 | J37: 1500000 | K37: =IFERROR(ROUND(J37*0.21,0),"") -> 315000 | L37: =IF(OR(G37="",I37=""),"",G37+I37) -> 1026060 | M37: =IF(OR(G37="",K37=""),"",G37+K37) -> 1078560
A38: Chungwoon University | B38: Applied Music | C38: No | D38: Yes | E38: Master | F38: 3636000 | G38: =IFERROR(ROUND(F38*0.21,0),"") -> 763560 | H38: 1250000 | I38: =IFERROR(ROUND(H38*0.21,0),"") -> 262500 | J38: 1500000 | K38: =IFERROR(ROUND(J38*0.21,0),"") -> 315000 | L38: =IF(OR(G38="",I38=""),"",G38+I38) -> 1026060 | M38: =IF(OR(G38="",K38=""),"",G38+K38) -> 1078560
A39: Chungwoon University | B39: Department of Regional Development and Space Design | C39: No | D39: Yes | E39: Master | F39: 3636000 | G39: =IFERROR(ROUND(F39*0.21,0),"") -> 763560 | H39: 1250000 | I39: =IFERROR(ROUND(H39*0.21,0),"") -> 262500 | J39: 1500000 | K39: =IFERROR(ROUND(J39*0.21,0),"") -> 315000 | L39: =IF(OR(G39="",I39=""),"",G39+I39) -> 1026060 | M39: =IF(OR(G39="",K39=""),"",G39+K39) -> 1078560
A40: Chungwoon University | B40: Culture and Arts Management (MICE) | C40: No | D40: Yes | E40: Master | F40: 3636000 | G40: =IFERROR(ROUND(F40*0.21,0),"") -> 763560 | H40: 1250000 | I40: =IFERROR(ROUND(H40*0.21,0),"") -> 262500 | J40: 1500000 | K40: =IFERROR(ROUND(J40*0.21,0),"") -> 315000 | L40: =IF(OR(G40="",I40=""),"",G40+I40) -> 1026060 | M40: =IF(OR(G40="",K40=""),"",G40+K40) -> 1078560
A41: Chungwoon University | B41: Department of Fashion Design | C41: No | D41: Yes | E41: Master | F41: 3636000 | G41: =IFERROR(ROUND(F41*0.21,0),"") -> 763560 | H41: 1250000 | I41: =IFERROR(ROUND(H41*0.21,0),"") -> 262500 | J41: 1500000 | K41: =IFERROR(ROUND(J41*0.21,0),"") -> 315000 | L41: =IF(OR(G41="",I41=""),"",G41+I41) -> 1026060 | M41: =IF(OR(G41="",K41=""),"",G41+K41) -> 1078560
A42: Chungwoon University | B42: Hotel Tourism Management | C42: No | D42: Yes | E42: Master | F42: 3267000 | G42: =IFERROR(ROUND(F42*0.21,0),"") -> 686070 | H42: 1250000 | I42: =IFERROR(ROUND(H42*0.21,0),"") -> 262500 | J42: 1500000 | K42: =IFERROR(ROUND(J42*0.21,0),"") -> 315000 | L42: =IF(OR(G42="",I42=""),"",G42+I42) -> 948570 | M42: =IF(OR(G42="",K42=""),"",G42+K42) -> 1001070
A43: Chungwoon University | B43: Tourism Management | C43: No | D43: Yes | E43: Master | F43: 3267000 | G43: =IFERROR(ROUND(F43*0.21,0),"") -> 686070 | H43: 1250000 | I43: =IFERROR(ROUND(H43*0.21,0),"") -> 262500 | J43: 1500000 | K43: =IFERROR(ROUND(J43*0.21,0),"") -> 315000 | L43: =IF(OR(G43="",I43=""),"",G43+I43) -> 948570 | M43: =IF(OR(G43="",K43=""),"",G43+K43) -> 1001070
A44: Chungwoon University | B44: Hotel Culinary & Catering Management | C44: No | D44: Yes | E44: Master | F44: 3267000 | G44: =IFERROR(ROUND(F44*0.21,0),"") -> 686070 | H44: 1250000 | I44: =IFERROR(ROUND(H44*0.21,0),"") -> 262500 | J44: 1500000 | K44: =IFERROR(ROUND(J44*0.21,0),"") -> 315000 | L44: =IF(OR(G44="",I44=""),"",G44+I44) -> 948570 | M44: =IF(OR(G44="",K44=""),"",G44+K44) -> 1001070
...

Sheet Jeonbok National (Jeonju)
A1: University | B1: Major | C1: English Medium | D1: Korean Medium | E1: Degree Type | F1: Tuition Fee (KRW) | G1: Tuition Fee (LKR) | H1: Dorm Option 1 (USD approx) | I1: Dorm Option 1 (LKR approx) | J1: Total with Dorm Option 1 (LKR approx) | K1: Dorm Option 2 (USD approx) | L1: Dorm Option 2 (LKR approx) | M1: Total with Dorm Option 2 (LKR approx) | N1: Dorm Option 3 (USD approx) | O1: Dorm Option 3 (LKR approx) | P1: Total with Dorm Option 3 (LKR approx)
A2: Jeonbuk National University (JBNU) | B2: Global Commerce | C2: No | D2: Yes | E2: Bachelor | F2: 2016000 | G2: =IF(F2="","",F2*Parameters!$B$1) -> 423360 | H2: 1000 | I2: =IF(H2="","",H2*Parameters!$B$2) -> 320000 | J2: =IF(OR(G2="",I2=""),"",G2+I2) -> 743360 | K2: 450 | L2: =IF(K2="","",K2*Parameters!$B$2) -> 144000 | M2: =IF(OR(G2="",L2=""),"",G2+L2) -> 567360 | N2: 520 | O2: =IF(N2="","",N2*Parameters!$B$2) -> 166400 | P2: =IF(OR(G2="",O2=""),"",G2+O2) -> 589760
A3: Jeonbuk National University (JBNU) | B3: Korean Language | C3: No | D3: Yes | E3: Bachelor | F3: 2016000 | G3: =IF(F3="","",F3*Parameters!$B$1) -> 423360 | H3: 1000 | I3: =IF(H3="","",H3*Parameters!$B$2) -> 320000 | J3: =IF(OR(G3="",I3=""),"",G3+I3) -> 743360 | K3: 450 | L3: =IF(K3="","",K3*Parameters!$B$2) -> 144000 | M3: =IF(OR(G3="",L3=""),"",G3+L3) -> 567360 | N3: 520 | O3: =IF(N3="","",N3*Parameters!$B$2) -> 166400 | P3: =IF(OR(G3="",O3=""),"",G3+O3) -> 589760
A4: Jeonbuk National University (JBNU) | B4: K-entertainment | C4: No | D4: Yes | E4: Bachelor | F4: 2016000 | G4: =IF(F4="","",F4*Parameters!$B$1) -> 423360 | H4: 1000 | I4: =IF(H4="","",H4*Parameters!$B$2) -> 320000 | J4: =IF(OR(G4="",I4=""),"",G4+I4) -> 743360 | K4: 450 | L4: =IF(K4="","",K4*Parameters!$B$2) -> 144000 | M4: =IF(OR(G4="",L4=""),"",G4+L4) -> 567360 | N4: 520 | O4: =IF(N4="","",N4*Parameters!$B$2) -> 166400 | P4: =IF(OR(G4="",O4=""),"",G4+O4) -> 589760
A5: Jeonbuk National University (JBNU) | B5: Major of Engineering and Science | C5: Yes | D5: No | E5: Bachelor | F5: 2016000 | G5: =IF(F5="","",F5*Parameters!$B$1) -> 423360 | H5: 1000 | I5: =IF(H5="","",H5*Parameters!$B$2) -> 320000 | J5: =IF(OR(G5="",I5=""),"",G5+I5) -> 743360 | K5: 450 | L5: =IF(K5="","",K5*Parameters!$B$2) -> 144000 | M5: =IF(OR(G5="",L5=""),"",G5+L5) -> 567360 | N5: 520 | O5: =IF(N5="","",N5*Parameters!$B$2) -> 166400 | P5: =IF(OR(G5="",O5=""),"",G5+O5) -> 589760
A6: Jeonbuk National University (JBNU) | B6: International Studies Major | C6: Yes | D6: No | E6: Bachelor | F6: 2016000 | G6: =IF(F6="","",F6*Parameters!$B$1) -> 423360 | H6: 1000 | I6: =IF(H6="","",H6*Parameters!$B$2) -> 320000 | J6: =IF(OR(G6="",I6=""),"",G6+I6) -> 743360 | K6: 450 | L6: =IF(K6="","",K6*Parameters!$B$2) -> 144000 | M6: =IF(OR(G6="",L6=""),"",G6+L6) -> 567360 | N6: 520 | O6: =IF(N6="","",N6*Parameters!$B$2) -> 166400 | P6: =IF(OR(G6="",O6=""),"",G6+O6) -> 589760
A7: Jeonbuk National University (JBNU) | B7: Department of Architectural Engineering | C7: No | D7: Yes | E7: Bachelor | F7: 2704000 | G7: =IF(F7="","",F7*Parameters!$B$1) -> 567840 | H7: 1000 | I7: =IF(H7="","",H7*Parameters!$B$2) -> 320000 | J7: =IF(OR(G7="",I7=""),"",G7+I7) -> 887840 | K7: 450 | L7: =IF(K7="","",K7*Parameters!$B$2) -> 144000 | M7: =IF(OR(G7="",L7=""),"",G7+L7) -> 711840 | N7: 520 | O7: =IF(N7="","",N7*Parameters!$B$2) -> 166400 | P7: =IF(OR(G7="",O7=""),"",G7+O7) -> 734240
A8: Jeonbuk National University (JBNU) | B8: Department of Polymer-Nano Science & Technology | C8: No | D8: Yes | E8: Bachelor | F8: 2016000 | G8: =IF(F8="","",F8*Parameters!$B$1) -> 423360 | H8: 1000 | I8: =IF(H8="","",H8*Parameters!$B$2) -> 320000 | J8: =IF(OR(G8="",I8=""),"",G8+I8) -> 743360 | K8: 450 | L8: =IF(K8="","",K8*Parameters!$B$2) -> 144000 | M8: =IF(OR(G8="",L8=""),"",G8+L8) -> 567360 | N8: 520 | O8: =IF(N8="","",N8*Parameters!$B$2) -> 166400 | P8: =IF(OR(G8="",O8=""),"",G8+O8) -> 589760
A9: Jeonbuk National University (JBNU) | B9: Department of Organic Materials and Textile Engineering | C9: No | D9: Yes | E9: Bachelor | F9: 2016000 | G9: =IF(F9="","",F9*Parameters!$B$1) -> 423360 | H9: 1000 | I9: =IF(H9="","",H9*Parameters!$B$2) -> 320000 | J9: =IF(OR(G9="",I9=""),"",G9+I9) -> 743360 | K9: 450 | L9: =IF(K9="","",K9*Parameters!$B$2) -> 144000 | M9: =IF(OR(G9="",L9=""),"",G9+L9) -> 567360 | N9: 520 | O9: =IF(N9="","",N9*Parameters!$B$2) -> 166400 | P9: =IF(OR(G9="",O9=""),"",G9+O9) -> 589760
A10: Jeonbuk National University (JBNU) | B10: Department of Mechanical Engineering | C10: No | D10: Yes | E10: Bachelor | F10: 2704000 | G10: =IF(F10="","",F10*Parameters!$B$1) -> 567840 | H10: 1000 | I10: =IF(H10="","",H10*Parameters!$B$2) -> 320000 | J10: =IF(OR(G10="",I10=""),"",G10+I10) -> 887840 | K10: 450 | L10: =IF(K10="","",K10*Parameters!$B$2) -> 144000 | M10: =IF(OR(G10="",L10=""),"",G10+L10) -> 711840 | N10: 520 | O10: =IF(N10="","",N10*Parameters!$B$2) -> 166400 | P10: =IF(OR(G10="",O10=""),"",G10+O10) -> 734240
A11: Jeonbuk National University (JBNU) | B11: Division of Mechanical Design Engineering (Major of Mechanical Design Engineering) | C11: No | D11: Yes | E11: Bachelor | F11: 2704000 | G11: =IF(F11="","",F11*Parameters!$B$1) -> 567840 | H11: 1000 | I11: =IF(H11="","",H11*Parameters!$B$2) -> 320000 | J11: =IF(OR(G11="",I11=""),"",G11+I11) -> 887840 | K11: 450 | L11: =IF(K11="","",K11*Parameters!$B$2) -> 144000 | M11: =IF(OR(G11="",L11=""),"",G11+L11) -> 711840 | N11: 520 | O11: =IF(N11="","",N11*Parameters!$B$2) -> 166400 | P11: =IF(OR(G11="",O11=""),"",G11+O11) -> 734240
A12: Jeonbuk National University (JBNU) | B12: Division of Mechanical Design Engineering (Major of Nano-bio Mechanical System Engineering) | C12: No | D12: Yes | E12: Bachelor | F12: 2704000 | G12: =IF(F12="","",F12*Parameters!$B$1) -> 567840 | H12: 1000 | I12: =IF(H12="","",H12*Parameters!$B$2) -> 320000 | J12: =IF(OR(G12="",I12=""),"",G12+I12) -> 887840 | K12: 450 | L12: =IF(K12="","",K12*Parameters!$B$2) -> 144000 | M12: =IF(OR(G12="",L12=""),"",G12+L12) -> 711840 | N12: 520 | O12: =IF(N12="","",N12*Parameters!$B$2) -> 166400 | P12: =IF(OR(G12="",O12=""),"",G12+O12) -> 734240
A13: Jeonbuk National University (JBNU) | B13: Division of Mechanical System Engineering | C13: No | D13: Yes | E13: Bachelor | F13: 2704000 | G13: =IF(F13="","",F13*Parameters!$B$1) -> 567840 | H13: 1000 | I13: =IF(H13="","",H13*Parameters!$B$2) -> 320000 | J13: =IF(OR(G13="",I13=""),"",G13+I13) -> 887840 | K13: 450 | L13: =IF(K13="","",K13*Parameters!$B$2) -> 144000 | M13: =IF(OR(G13="",L13=""),"",G13+L13) -> 711840 | N13: 520 | O13: =IF(N13="","",N13*Parameters!$B$2) -> 166400 | P13: =IF(OR(G13="",O13=""),"",G13+O13) -> 734240
... A385: Jeonbuk National University (JBNU) | B385: Korean Music(Gayageum · Geomungo, Ajaeng · Daegeum · Piri · Haegeum, Percussion, Pansori, Composition, Theory, Arts Management) | C385: No | D385: Yes | E385: PhD | F385: 4076500 | G385: =IF(F385="","",F385*Parameters!$B$1) -> 856065 | H385: 1100 | I385: =IF(H385="","",H385*Parameters!$B$2) -> 352000 | J385: =IF(OR(G385="",I385=""),"",G385+I385) -> 1208065 | K385: 1200 | L385: =IF(K385="","",K385*Parameters!$B$2) -> 384000 | M385: =IF(OR(G385="",L385=""),"",G385+L385) -> 1240065 | N385: 500 | O385: =IF(N385="","",N385*Parameters!$B$2) -> 160000 | P385: =IF(OR(G385="",O385=""),"",G385+O385) -> 1016065

Sheet KIT (Busan)
A1: University | B1: Major | C1: English Medium | D1: Korean Medium | E1: Degree Type | F1: Tuition Fee (KRW) | G1: Tuition Fee (LKR) | H1: Dorm Option 1 (KRW) | I1: Dorm Per Semester (LKR approx) | J1: Total with Dorm (LKR approx)
A2: Kyungnam College of Information and Technology | B2: Department of Electronic Engineering | C2: No | D2: Yes | E2: Associate Degree (2Yrs) | F2: 3468300 | G2: =IF(F2="","",F2*Parameters!$B$1) -> 728343 | H2: 1050000 | I2: =IF(H2="","",H2*Parameters!$B$1) -> 220500 | J2: =IF(OR(G2="",I2=""),"",G2+I2) -> 948843
A3: Kyungnam College of Information and Technology | B3: Department of Electrical Engineering | C3: No | D3: Yes | E3: Associate Degree (2Yrs) | F3: 3468300 | G3: =IF(F3="","",F3*Parameters!$B$1) -> 728343 | H3: 1050000 | I3: =IF(H3="","",H3*Parameters!$B$1) -> 220500 | J3: =IF(OR(G3="",I3=""),"",G3+I3) -> 948843
A4: Kyungnam College of Information and Technology | B4: Department of Mechanical Engineering | C4: No | D4: Yes | E4: Associate Degree (2Yrs) | F4: 3468300 | G4: =IF(F4="","",F4*Parameters!$B$1) -> 728343 | H4: 1050000 | I4: =IF(H4="","",H4*Parameters!$B$1) -> 220500 | J4: =IF(OR(G4="",I4=""),"",G4+I4) -> 948843
A5: Kyungnam College of Information and Technology | B5: Department of Electric and Hydrogen Vehicles | C5: No | D5: Yes | E5: Associate Degree (2Yrs) | F5: 3468300 | G5: =IF(F5="","",F5*Parameters!$B$1) -> 728343 | H5: 1050000 | I5: =IF(H5="","",H5*Parameters!$B$1) -> 220500 | J5: =IF(OR(G5="",I5=""),"",G5+I5) -> 948843
A6: Kyungnam College of Information and Technology | B6: Department of Chemical and Energy Engineering | C6: No | D6: Yes | E6: Associate Degree (2Yrs) | F6: 3468300 | G6: =IF(F6="","",F6*Parameters!$B$1) -> 728343 | H6: 1050000 | I6: =IF(H6="","",H6*Parameters!$B$1) -> 220500 | J6: =IF(OR(G6="",I6=""),"",G6+I6) -> 948843
A7: Kyungnam College of Information and Technology | B7: Department of Computer Science | C7: No | D7: Yes | E7: Associate Degree (2Yrs) | F7: 3468300 | G7: =IF(F7="","",F7*Parameters!$B$1) -> 728343 | H7: 1050000 | I7: =IF(H7="","",H7*Parameters!$B$1) -> 220500 | J7: =IF(OR(G7="",I7=""),"",G7+I7) -> 948843
A8: Kyungnam College of Information and Technology | B8: Department of Interior Design | C8: No | D8: Yes | E8: Associate Degree (2Yrs) | F8: 3468300 | G8: =IF(F8="","",F8*Parameters!$B$1) -> 728343 | H8: 1050000 | I8: =IF(H8="","",H8*Parameters!$B$1) -> 220500 | J8: =IF(OR(G8="",I8=""),"",G8+I8) -> 948843
A9: Kyungnam College of Information and Technology | B9: Department of Civil and Environmental Engineering | C9: No | D9: Yes | E9: Associate Degree (2Yrs) | F9: 3468300 | G9: =IF(F9="","",F9*Parameters!$B$1) -> 728343 | H9: 1050000 | I9: =IF(H9="","",H9*Parameters!$B$1) -> 220500 | J9: =IF(OR(G9="",I9=""),"",G9+I9) -> 948843
A10: Kyungnam College of Information and Technology | B10: Department of Environmental Landscape Design | C10: No | D10: Yes | E10: Associate Degree (2Yrs) | F10: 3468300 | G10: =IF(F10="","",F10*Parameters!$B$1) -> 728343 | H10: 1050000 | I10: =IF(H10="","",H10*Parameters!$B$1) -> 220500 | J10: =IF(OR(G10="",I10=""),"",G10+I10) -> 948843
A11: Kyungnam College of Information and Technology | B11: Department of Media and Image | C11: No | D11: Yes | E11: Associate Degree (2Yrs) | F11: 3468300 | G11: =IF(F11="","",F11*Parameters!$B$1) -> 728343 | H11: 1050000 | I11: =IF(H11="","",H11*Parameters!$B$1) -> 220500 | J11: =IF(OR(G11="",I11=""),"",G11+I11) -> 948843
A12: Kyungnam College of Information and Technology | B12: Department of Fire Safety Management | C12: No | D12: Yes | E12: Associate Degree (2Yrs) | F12: 3468300 | G12: =IF(F12="","",F12*Parameters!$B$1) -> 728343 | H12: 1050000 | I12: =IF(H12="","",H12*Parameters!$B$1) -> 220500 | J12: =IF(OR(G12="",I12=""),"",G12+I12) -> 948843
A13: Kyungnam College of Information and Technology | B13: Department of Footwear and Fashion | C13: No | D13: Yes | E13: Associate Degree (2Yrs) | F13: 3468300 | G13: =IF(F13="","",F13*Parameters!$B$1) -> 728343 | H13: 1050000 | I13: =IF(H13="","",H13*Parameters!$B$1) -> 220500 | J13: =IF(OR(G13="",I13=""),"",G13+I13) -> 948843
... A38: Kyungnam College of Information and Technology | B38: Digital Literature Creation Division | C38: No | D38: Yes | E38: Associate Degree (2Yrs) | F38: 3403300 | G38: =IF(F38="","",F38*Parameters!$B$1) -> 714693 | H38: 1050000 | I38: =IF(H38="","",H38*Parameters!$B$1) -> 220500 | J38: =IF(OR(G38="",I38=""),"",G38+I38) -> 935193

Sheet Woosong university (Daejon)
A1: University | B1: Major / Program | C1: English Medium | D1: Korean Medium | E1: Degree Type | F1: Tuition Fee (USD) | G1: Tuition Fee (LKR) | H1: Dorm Option A - Room & Board (Academic Year, 1 meal/day) (USD) | I1: Dorm Option A - Room & Board (Academic Year, 1 meal/day) (LKR) | J1: Dorm Option B - Room & Board (Summer/Winter, per semester) (USD) | K1: Dorm Option B - Room & Board (Summer/Winter, per semester) (LKR) | L1: Total with Dorm Option A (LKR) | M1: Total with Dorm Option B (LKR)
A2: Woosong University (WSU), South Korea | B2: AI and Big Data | C2: Yes | D2: No | E2: Bachelor | F2: 3897 | G2: =IFERROR(ROUND(F2*309.65,0),"") -> 1206706 | H2: 2352 | I2: =IFERROR(ROUND(H2*309.65,0),"") -> 728297 | J2: 340 | K2: =IFERROR(ROUND(J2*309.65,0),"") -> 105281 | L2: =IF(OR(G2="",I2=""),"",G2+I2) -> 1935003 | M2: =IF(OR(G2="",K2=""),"",G2+K2) -> 1311987
A3: Woosong University (WSU), South Korea | B3: Business Administration (AACSB accredited) | C3: Yes | D3: No | E3: Bachelor | F3: 6296 | G3: =IFERROR(ROUND(F3*309.65,0),"") -> 1949556 | H3: 2352 | I3: =IFERROR(ROUND(H3*309.65,0),"") -> 728297 | J3: 340 | K3: =IFERROR(ROUND(J3*309.65,0),"") -> 105281 | L3: =IF(OR(G3="",I3=""),"",G3+I3) -> 2677853 | M3: =IF(OR(G3="",K3=""),"",G3+K3) -> 2054837
A4: Woosong University (WSU), South Korea | B4: Global Hospitality (formerly known as Global Hotel Management) | C4: Yes | D4: No | E4: Bachelor | F4: 3396 | G4: =IFERROR(ROUND(F4*309.65,0),"") -> 1051571 | H4: 2352 | I4: =IFERROR(ROUND(H4*309.65,0),"") -> 728297 | J4: 340 | K4: =IFERROR(ROUND(J4*309.65,0),"") -> 105281 | L4: =IF(OR(G4="",I4=""),"",G4+I4) -> 1779868 | M4: =IF(OR(G4="",K4=""),"",G4+K4) -> 1156852
A5: Woosong University (WSU), South Korea | B5: AI Management (formerly known as Global Management) | C5: Yes | D5: No | E5: Bachelor | F5: 3396 | G5: =IFERROR(ROUND(F5*309.65,0),"") -> 1051571 | H5: 2352 | I5: =IFERROR(ROUND(H5*309.65,0),"") -> 728297 | J5: 340 | K5: =IFERROR(ROUND(J5*309.65,0),"") -> 105281 | L5: =IF(OR(G5="",I5=""),"",G5+I5) -> 1779868 | M5: =IF(OR(G5="",K5=""),"",G5+K5) -> 1156852
A6: Woosong University (WSU), South Korea | B6: Media and Communication Arts | C6: Yes | D6: No | E6: Bachelor | F6: 3897 | G6: =IFERROR(ROUND(F6*309.65,0),"") -> 1206706 | H6: 2352 | I6: =IFERROR(ROUND(H6*309.65,0),"") -> 728297 | J6: 340 | K6: =IFERROR(ROUND(J6*309.65,0),"") -> 105281 | L6: =IF(OR(G6="",I6=""),"",G6+I6) -> 1935003 | M6: =IF(OR(G6="",K6=""),"",G6+K6) -> 1311987
A7: Woosong University (WSU), South Korea | B7: Global Culinary Arts | C7: Yes | D7: No | E7: Bachelor | F7: 4221 | G7: =IFERROR(ROUND(F7*309.65,0),"") -> 1307033 | H7: 2352 | I7: =IFERROR(ROUND(H7*309.65,0),"") -> 728297 | J7: 340 | K7: =IFERROR(ROUND(J7*309.65,0),"") -> 105281 | L7: =IF(OR(G7="",I7=""),"",G7+I7) -> 2035330 | M7: =IF(OR(G7="",K7=""),"",G7+K7) -> 1412314
A8: Woosong University (WSU), South Korea | B8: Global Restaurant Management (formerly known as Restaurant Entrepreneurship) | C8: Yes | D8: No | E8: Bachelor | F8: 4221 | G8: =IFERROR(ROUND(F8*309.65,0),"") -> 1307033 | H8: 2352 | I8: =IFERROR(ROUND(H8*309.65,0),"") -> 728297 | J8: 340 | K8: =IFERROR(ROUND(J8*309.65,0),"") -> 105281 | L8: =IF(OR(G8="",I8=""),"",G8+I8) -> 2035330 | M8: =IF(OR(G8="",K8=""),"",G8+K8) -> 1412314
A9: Woosong University (WSU), South Korea | B9: AI | C9: Yes | D9: No | E9: Bachelor | F9: 5247 | G9: =IFERROR(ROUND(F9*309.65,0),"") -> 1624734 | H9: 2352 | I9: =IFERROR(ROUND(H9*309.65,0),"") -> 728297 | J9: 340 | K9: =IFERROR(ROUND(J9*309.65,0),"") -> 105281 | L9: =IF(OR(G9="",I9=""),"",G9+I9) -> 2353031 | M9: =IF(OR(G9="",K9=""),"",G9+K9) -> 1730015
A10: Woosong University (WSU), South Korea | B10: Data Science | C10: Yes | D10: No | E10: Bachelor | F10: 5247 | G10: =IFERROR(ROUND(F10*309.65,0),"") -> 1624734 | H10: 2352 | I10: =IFERROR(ROUND(H10*309.65,0),"") -> 728297 | J10: 340 | K10: =IFERROR(ROUND(J10*309.65,0),"") -> 105281 | L10: =IF(OR(G10="",I10=""),"",G10+I10) -> 2353031 | M10: =IF(OR(G10="",K10=""),"",G10+K10) -> 1730015
A11: Woosong University (WSU), South Korea | B11: K-Beauty Design | C11: Yes | D11: No | E11: Bachelor | F11: 3999 | G11: =IFERROR(ROUND(F11*309.65,0),"") -> 1238290 | H11: 2352 | I11: =IFERROR(ROUND(H11*309.65,0),"") -> 728297 | J11: 340 | K11: =IFERROR(ROUND(J11*309.65,0),"") -> 105281 | L11: =IF(OR(G11="",I11=""),"",G11+I11) -> 1966587 | M11: =IF(OR(G11="",K11=""),"",G11+K11) -> 1343571
A12: Woosong University (WSU), South Korea | B12: Global Railroad | C12: Yes | D12: No | E12: Bachelor | F12: 3897 | G12: =IFERROR(ROUND(F12*309.65,0),"") -> 1206706 | H12: 2352 | I12: =IFERROR(ROUND(H12*309.65,0),"") -> 728297 | J12: 340 | K12: =IFERROR(ROUND(J12*309.65,0),"") -> 105281 | L12: =IF(OR(G12="",I12=""),"",G12+I12) -> 1935003 | M12: =IF(OR(G12="",K12=""),"",G12+K12) -> 1311987
A13: Woosong University (WSU), South Korea | B13: Early Childhood Education | C13: Yes | D13: No | E13: Bachelor | F13: 3396 | G13: =IFERROR(ROUND(F13*309.65,0),"") -> 1051571 | H13: 2352 | I13: =IFERROR(ROUND(H13*309.65,0),"") -> 728297 | J13: 340 | K13: =IFERROR(ROUND(J13*309.65,0),"") -> 105281 | L13: =IF(OR(G13="",I13=""),"",G13+I13) -> 1779868 | M13: =IF(OR(G13="",K13=""),"",G13+K13) -> 1156852
... A26: Woosong University (WSU), South Korea | B26: Ph.D. in Design Management | C26: Yes | D26: No | E26: PhD | F26: 4875 | G26: =IFERROR(ROUND(F26*309.65,0),"") -> 1509544 | H26: 2352 | I26: =IFERROR(ROUND(H26*309.65,0),"") -> 728297 | J26: 340 | K26: =IFERROR(ROUND(J26*309.65,0),"") -> 105281 | L26: =IF(OR(G26="",I26=""),"",G26+I26) -> 2237841 | M26: =IF(OR(G26="",K26=""),"",G26+K26) -> 1614825

Sheet Jeonju University (Jeonju)
A1: University | B1: Major | C1: English Medium | D1: Korean Medium | E1: Degree Type | F1: Tuition Fee (KRW) | G1: Tuition Fee (LKR) | H1: Dorm Option 1 (KRW approx) | I1: Dorm Option 1 (LKR approx) | J1: Total with Dorm Option 1 (LKR approx) | K1: Dorm Option 2 (KRW approx) | L1: Dorm Option 2 (LKR approx) | M1: Total with Dorm Option 2 (LKR approx) | N1: Dorm Option 3 (KRW approx) | O1: Dorm Option 3 (LKR approx) | P1: Total with Dorm Option 3 (LKR approx) | Q1: Dorm Option 4 (KRW approx) | R1: Dorm Option 4 (LKR approx) | S1: Total with Dorm Option 4 (LKR approx)
A2: Jeonju University | B2: Business Administration | C2: Yes | D2: No | E2: Bachelor | F2: 3915000 | G2: =IF(F2="","",F2*Parameters!$B$1) -> 822150 | H2: 1890000 | I2: =IF(H2="","",H2*Parameters!$B$1) -> 396900 | J2: =IF(OR(G2="",I2=""),"",G2+I2) -> 1219050 | K2: 1252000 | L2: =IF(K2="","",K2*Parameters!$B$1) -> 262920 | M2: =IF(OR(G2="",L2=""),"",G2+L2) -> 1085070 | N2: 1192600 | O2: =IF(N2="","",N2*Parameters!$B$1) -> 250446 | P2: =IF(OR(G2="",O2=""),"",G2+O2) -> 1072596 | Q2: 869000 | R2: =IF(Q2="","",Q2*Parameters!$B$1) -> 182490 | S2: =IF(OR(G2="",R2=""),"",G2+R2) -> 1004640
A3: Jeonju University | B3: International Hospitality and Tourism Management | C3: Yes | D3: No | E3: Bachelor | F3: 3915000 | G3: =IF(F3="","",F3*Parameters!$B$1) -> 822150 | H3: 1890000 | I3: =IF(H3="","",H3*Parameters!$B$1) -> 396900 | J3: =IF(OR(G3="",I3=""),"",G3+I3) -> 1219050 | K3: 1252000 | L3: =IF(K3="","",K3*Parameters!$B$1) -> 262920 | M3: =IF(OR(G3="",L3=""),"",G3+L3) -> 1085070 | N3: 1192600 | O3: =IF(N3="","",N3*Parameters!$B$1) -> 250446 | P3: =IF(OR(G3="",O3=""),"",G3+O3) -> 1072596 | Q3: 869000 | R3: =IF(Q3="","",Q3*Parameters!$B$1) -> 182490 | S3: =IF(OR(G3="",R3=""),"",G3+R3) -> 1004640
A4: Jeonju University | B4: History and Cultural Contents | C4: No | D4: Yes | E4: Bachelor | F4: 3665000 | G4: =IF(F4="","",F4*Parameters!$B$1) -> 769650 | H4: 1890000 | I4: =IF(H4="","",H4*Parameters!$B$1) -> 396900 | J4: =IF(OR(G4="",I4=""),"",G4+I4) -> 1166550 | K4: 1252000 | L4: =IF(K4="","",K4*Parameters!$B$1) -> 262920 | M4: =IF(OR(G4="",L4=""),"",G4+L4) -> 1032570 | N4: 1192600 | O4: =IF(N4="","",N4*Parameters!$B$1) -> 250446 | P4: =IF(OR(G4="",O4=""),"",G4+O4) -> 1020096 | Q4: 869000 | R4: =IF(Q4="","",Q4*Parameters!$B$1) -> 182490 | S4: =IF(OR(G4="",R4=""),"",G4+R4) -> 952140
A5: Jeonju University | B5: English Language and Literature | C5: No | D5: Yes | E5: Bachelor | F5: 3665000 | G5: =IF(F5="","",F5*Parameters!$B$1) -> 769650 | H5: 1890000 | I5: =IF(H5="","",H5*Parameters!$B$1) -> 396900 | J5: =IF(OR(G5="",I5=""),"",G5+I5) -> 1166550 | K5: 1252000 | L5: =IF(K5="","",K5*Parameters!$B$1) -> 262920 | M5: =IF(OR(G5="",L5=""),"",G5+L5) -> 1032570 | N5: 1192600 | O5: =IF(N5="","",N5*Parameters!$B$1) -> 250446 | P5: =IF(OR(G5="",O5=""),"",G5+O5) -> 1020096 | Q5: 869000 | R5: =IF(Q5="","",Q5*Parameters!$B$1) -> 182490 | S5: =IF(OR(G5="",R5=""),"",G5+R5) -> 952140
A6: Jeonju University | B6: Japanese Language and Culture | C6: No | D6: Yes | E6: Bachelor | F6: 3665000 | G6: =IF(F6="","",F6*Parameters!$B$1) -> 769650 | H6: 1890000 | I6: =IF(H6="","",H6*Parameters!$B$1) -> 396900 | J6: =IF(OR(G6="",I6=""),"",G6+I6) -> 1166550 | K6: 1252000 | L6: =IF(K6="","",K6*Parameters!$B$1) -> 262920 | M6: =IF(OR(G6="",L6=""),"",G6+L6) -> 1032570 | N6: 1192600 | O6: =IF(N6="","",N6*Parameters!$B$1) -> 250446 | P6: =IF(OR(G6="",O6=""),"",G6+O6) -> 1020096 | Q6: 869000 | R6: =IF(Q6="","",Q6*Parameters!$B$1) -> 182490 | S6: =IF(OR(G6="",R6=""),"",G6+R6) -> 952140
A7: Jeonju University | B7: Chinese Language and Sinology | C7: No | D7: Yes | E7: Bachelor | F7: 3665000 | G7: =IF(F7="","",F7*Parameters!$B$1) -> 769650 | H7: 1890000 | I7: =IF(H7="","",H7*Parameters!$B$1) -> 396900 | J7: =IF(OR(G7="",I7=""),"",G7+I7) -> 1166550 | K7: 1252000 | L7: =IF(K7="","",K7*Parameters!$B$1) -> 262920 | M7: =IF(OR(G7="",L7=""),"",G7+L7) -> 1032570 | N7: 1192600 | O7: =IF(N7="","",N7*Parameters!$B$1) -> 250446 | P7: =IF(OR(G7="",O7=""),"",G7+O7) -> 1020096 | Q7: 869000 | R7: =IF(Q7="","",Q7*Parameters!$B$1) -> 182490 | S7: =IF(OR(G7="",R7=""),"",G7+R7) -> 952140
A8: Jeonju University | B8: Korean Language and Culture Creation | C8: No | D8: Yes | E8: Bachelor | F8: 3665000 | G8: =IF(F8="","",F8*Parameters!$B$1) -> 769650 | H8: 1890000 | I8: =IF(H8="","",H8*Parameters!$B$1) -> 396900 | J8: =IF(OR(G8="",I8=""),"",G8+I8) -> 1166550 | K8: 1252000 | L8: =IF(K8="","",K8*Parameters!$B$1) -> 262920 | M8: =IF(OR(G8="",L8=""),"",G8+L8) -> 1032570 | N8: 1192600 | O8: =IF(N8="","",N8*Parameters!$B$1) -> 250446 | P8: =IF(OR(G8="",O8=""),"",G8+O8) -> 1020096 | Q8: 869000 | R8: =IF(Q8="","",Q8*Parameters!$B$1) -> 182490 | S8: =IF(OR(G8="",R8=""),"",G8+R8) -> 952140
A9: Jeonju University | B9: Police Science | C9: No | D9: Yes | E9: Bachelor | F9: 3665000 | G9: =IF(F9="","",F9*Parameters!$B$1) -> 769650 | H9: 1890000 | I9: =IF(H9="","",H9*Parameters!$B$1) -> 396900 | J9: =IF(OR(G9="",I9=""),"",G9+I9) -> 1166550 | K9: 1252000 | L9: =IF(K9="","",K9*Parameters!$B$1) -> 262920 | M9: =IF(OR(G9="",L9=""),"",G9+L9) -> 1032570 | N9: 1192600 | O9: =IF(N9="","",N9*Parameters!$B$1) -> 250446 | P9: =IF(OR(G9="",O9=""),"",G9+O9) -> 1020096 | Q9: 869000 | R9: =IF(Q9="","",Q9*Parameters!$B$1) -> 182490 | S9: =IF(OR(G9="",R9=""),"",G9+R9) -> 952140
A10: Jeonju University | B10: Library and Information Science | C10: No | D10: Yes | E10: Bachelor | F10: 3665000 | G10: =IF(F10="","",F10*Parameters!$B$1) -> 769650 | H10: 1890000 | I10: =IF(H10="","",H10*Parameters!$B$1) -> 396900 | J10: =IF(OR(G10="",I10=""),"",G10+I10) -> 1166550 | K10: 1252000 | L10: =IF(K10="","",K10*Parameters!$B$1) -> 262920 | M10: =IF(OR(G10="",L10=""),"",G10+L10) -> 1032570 | N10: 1192600 | O10: =IF(N10="","",N10*Parameters!$B$1) -> 250446 | P10: =IF(OR(G10="",O10=""),"",G10+O10) -> 1020096 | Q10: 869000 | R10: =IF(Q10="","",Q10*Parameters!$B$1) -> 182490 | S10: =IF(OR(G10="",R10=""),"",G10+R10) -> 952140
A11: Jeonju University | B11: Law | C11: No | D11: Yes | E11: Bachelor | F11: 3665000 | G11: =IF(F11="","",F11*Parameters!$B$1) -> 769650 | H11: 1890000 | I11: =IF(H11="","",H11*Parameters!$B$1) -> 396900 | J11: =IF(OR(G11="",I11=""),"",G11+I11) -> 1166550 | K11: 1252000 | L11: =IF(K11="","",K11*Parameters!$B$1) -> 262920 | M11: =IF(OR(G11="",L11=""),"",G11+L11) -> 1032570 | N11: 1192600 | O11: =IF(N11="","",N11*Parameters!$B$1) -> 250446 | P11: =IF(OR(G11="",O11=""),"",G11+O11) -> 1020096 | Q11: 869000 | R11: =IF(Q11="","",Q11*Parameters!$B$1) -> 182490 | S11: =IF(OR(G11="",R11=""),"",G11+R11) -> 952140
A12: Jeonju University | B12: Social Welfare | C12: No | D12: Yes | E12: Bachelor | F12: 3665000 | G12: =IF(F12="","",F12*Parameters!$B$1) -> 769650 | H12: 1890000 | I12: =IF(H12="","",H12*Parameters!$B$1) -> 396900 | J12: =IF(OR(G12="",I12=""),"",G12+I12) -> 1166550 | K12: 1252000 | L12: =IF(K12="","",K12*Parameters!$B$1) -> 262920 | M12: =IF(OR(G12="",L12=""),"",G12+L12) -> 1032570 | N12: 1192600 | O12: =IF(N12="","",N12*Parameters!$B$1) -> 250446 | P12: =IF(OR(G12="",O12=""),"",G12+O12) -> 1020096 | Q12: 869000 | R12: =IF(Q12="","",Q12*Parameters!$B$1) -> 182490 | S12: =IF(OR(G12="",R12=""),"",G12+R12) -> 952140
A13: Jeonju University | B13: Counseling Psychology | C13: No | D13: Yes | E13: Bachelor | F13: 3665000 | G13: =IF(F13="","",F13*Parameters!$B$1) -> 769650 | H13: 1890000 | I13: =IF(H13="","",H13*Parameters!$B$1) -> 396900 | J13: =IF(OR(G13="",I13=""),"",G13+I13) -> 1166550 | K13: 1252000 | L13: =IF(K13="","",K13*Parameters!$B$1) -> 262920 | M13: =IF(OR(G13="",L13=""),"",G13+L13) -> 1032570 | N13: 1192600 | O13: =IF(N13="","",N13*Parameters!$B$1) -> 250446 | P13: =IF(OR(G13="",O13=""),"",G13+O13) -> 1020096 | Q13: 869000 | R13: =IF(Q13="","",Q13*Parameters!$B$1) -> 182490 | S13: =IF(OR(G13="",R13=""),"",G13+R13) -> 952140
... A51: Jeonju University | B51: Computer Science and Engineering | C51: No | D51: Yes | E51: Bachelor | F51: 4788000 | G51: =IF(F51="","",F51*Parameters!$B$1) -> 1005480 | H51: 1890000 | I51: =IF(H51="","",H51*Parameters!$B$1) -> 396900 | J51: =IF(OR(G51="",I51=""),"",G51+I51) -> 1402380 | K51: 1252000 | L51: =IF(K51="","",K51*Parameters!$B$1) -> 262920 | M51: =IF(OR(G51="",L51=""),"",G51+L51) -> 1268400 | N51: 1192600 | O51: =IF(N51="","",N51*Parameters!$B$1) -> 250446 | P51: =IF(OR(G51="",O51=""),"",G51+O51) -> 1255926 | Q51: 869000 | R51: =IF(Q51="","",Q51*Parameters!$B$1) -> 182490 | S51: =IF(OR(G51="",R51=""),"",G51+R51) -> 1187970
A52: MASTERS | E52: ADMISSION FEE | F52: 650000 | G52: =IF(F52="","",F52*Parameters!$B$1) -> 136500 | J52: =IF(OR(G52="",I52=""),"",G52+I52) | M52: =IF(OR(G52="",L52=""),"",G52+L52) | P52: =IF(OR(G52="",O52=""),"",G52+O52)
A53: Jeonju University | B53: IT Accounting & Finance | C53: No | D53: Yes | E53: Masters | F53: 4574000 | G53: =IF(F53="","",F53*Parameters!$B$1) -> 960540 | H53: 1890000 | I53: =IF(H53="","",H53*Parameters!$B$1) -> 396900 | J53: =IF(OR(G53="",I53=""),"",G53+I53) -> 1357440 | K53: 1252000 | L53: =IF(K53="","",K53*Parameters!$B$1) -> 262920 | M53: =IF(OR(G53="",L53=""),"",G53+L53) -> 1223460 | N53: 1192600 | O53: =IF(N53="","",N53*Parameters!$B$1) -> 250446 | P53: =IF(OR(G53="",O53=""),"",G53+O53) -> 1210986
A54: Jeonju University | B54: Business Administration | C54: No | D54: Yes | E54: Masters | F54: 4574000 | G54: =IF(F54="","",F54*Parameters!$B$1) -> 960540 | H54: 1890000 | I54: =IF(H54="","",H54*Parameters!$B$1) -> 396900 | J54: =IF(OR(G54="",I54=""),"",G54+I54) -> 1357440 | K54: 1252000 | L54: =IF(K54="","",K54*Parameters!$B$1) -> 262920 | M54: =IF(OR(G54="",L54=""),"",G54+L54) -> 1223460 | N54: 1192600 | O54: =IF(N54="","",N54*Parameters!$B$1) -> 250446 | P54: =IF(OR(G54="",O54=""),"",G54+O54) -> 1210986
A55: Jeonju University | B55: Tourism Management | C55: No | D55: Yes | E55: Masters | F55: 4574000 | G55: =IF(F55="","",F55*Parameters!$B$1) -> 960540 | H55: 1890000 | I55: =IF(H55="","",H55*Parameters!$B$1) -> 396900 | J55: =IF(OR(G55="",I55=""),"",G55+I55) -> 1357440 | K55: 1252000 | L55: =IF(K55="","",K55*Parameters!$B$1) -> 262920 | M55: =IF(OR(G55="",L55=""),"",G55+L55) -> 1223460 | N55: 1192600 | O55: =IF(N55="","",N55*Parameters!$B$1) -> 250446 | P55: =IF(OR(G55="",O55=""),"",G55+O55) -> 1210986
A56: Jeonju University | B56: Education | C56: No | D56: Yes | E56: Masters | F56: 4574000 | G56: =IF(F56="","",F56*Parameters!$B$1) -> 960540 | H56: 1890000 | I56: =IF(H56="","",H56*Parameters!$B$1) -> 396900 | J56: =IF(OR(G56="",I56=""),"",G56+I56) -> 1357440 | K56: 1252000 | L56: =IF(K56="","",K56*Parameters!$B$1) -> 262920 | M56: =IF(OR(G56="",L56=""),"",G56+L56) -> 1223460 | N56: 1192600 | O56: =IF(N56="","",N56*Parameters!$B$1) -> 250446 | P56: =IF(OR(G56="",O56=""),"",G56+O56) -> 1210986
A57: Jeonju University | B57: Korean Language and Literature | C57: No | D57: Yes | E57: Masters | F57: 4574000 | G57: =IF(F57="","",F57*Parameters!$B$1) -> 960540 | H57: 1890000 | I57: =IF(H57="","",H57*Parameters!$B$1) -> 396900 | J57: =IF(OR(G57="",I57=""),"",G57+I57) -> 1357440 | K57: 1252000 | L57: =IF(K57="","",K57*Parameters!$B$1) -> 262920 | M57: =IF(OR(G57="",L57=""),"",G57+L57) -> 1223460 | N57: 1192600 | O57: =IF(N57="","",N57*Parameters!$B$1) -> 250446 | P57: =IF(OR(G57="",O57=""),"",G57+O57) -> 1210986
A58: Jeonju University | B58: Finance and Insurance | C58: No | D58: Yes | E58: Masters | F58: 4574000 | G58: =IF(F58="","",F58*Parameters!$B$1) -> 960540 | H58: 1890000 | I58: =IF(H58="","",H58*Parameters!$B$1) -> 396900 | J58: =IF(OR(G58="",I58=""),"",G58+I58) -> 1357440 | K58: 1252000 | L58: =IF(K58="","",K58*Parameters!$B$1) -> 262920 | M58: =IF(OR(G58="",L58=""),"",G58+L58) -> 1223460 | N58: 1192600 | O58: =IF(N58="","",N58*Parameters!$B$1) -> 250446 | P58: =IF(OR(G58="",O58=""),"",G58+O58) -> 1210986
A59: Jeonju University | B59: Public Policy | C59: No | D59: Yes | E59: Masters | F59: 4574000 | G59: =IF(F59="","",F59*Parameters!$B$1) -> 960540 | H59: 1890000 | I59: =IF(H59="","",H59*Parameters!$B$1) -> 396900 | J59: =IF(OR(G59="",I59=""),"",G59+I59) -> 1357440 | K59: 1252000 | L59: =IF(K59="","",K59*Parameters!$B$1) -> 262920 | M59: =IF(OR(G59="",L59=""),"",G59+L59) -> 1223460 | N59: 1192600 | O59: =IF(N59="","",N59*Parameters!$B$1) -> 250446 | P59: =IF(OR(G59="",O59=""),"",G59+O59) -> 1210986
A60: Jeonju University | B60: Real Estate Studies | C60: No | D60: Yes | E60: Masters | F60: 4574000 | G60: =IF(F60="","",F60*Parameters!$B$1) -> 960540 | H60: 1890000 | I60: =IF(H60="","",H60*Parameters!$B$1) -> 396900 | J60: =IF(OR(G60="",I60=""),"",G60+I60) -> 1357440 | K60: 1252000 | L60: =IF(K60="","",K60*Parameters!$B$1) -> 262920 | M60: =IF(OR(G60="",L60=""),"",G60+L60) -> 1223460 | N60: 1192600 | O60: =IF(N60="","",N60*Parameters!$B$1) -> 250446 | P60: =IF(OR(G60="",O60=""),"",G60+O60) -> 1210986
A61: Jeonju University | B61: Private History | C61: No | D61: Yes | E61: Masters | F61: 4574000 | G61: =IF(F61="","",F61*Parameters!$B$1) -> 960540 | H61: 1890000 | I61: =IF(H61="","",H61*Parameters!$B$1) -> 396900 | J61: =IF(OR(G61="",I61=""),"",G61+I61) -> 1357440 | K61: 1252000 | L61: =IF(K61="","",K61*Parameters!$B$1) -> 262920 | M61: =IF(OR(G61="",L61=""),"",G61+L61) -> 1223460 | N61: 1192600 | O61: =IF(N61="","",N61*Parameters!$B$1) -> 250446 | P61: =IF(OR(G61="",O61=""),"",G61+O61) -> 1210986
A62: Jeonju University | B62: Social Welfare | C62: No | D62: Yes | E62: Masters | F62: 4574000 | G62: =IF(F62="","",F62*Parameters!$B$1) -> 960540 | H62: 1890000 | I62: =IF(H62="","",H62*Parameters!$B$1) -> 396900 | J62: =IF(OR(G62="",I62=""),"",G62+I62) -> 1357440 | K62: 1252000 | L62: =IF(K62="","",K62*Parameters!$B$1) -> 262920 | M62: =IF(OR(G62="",L62=""),"",G62+L62) -> 1223460 | N62: 1192600 | O62: =IF(N62="","",N62*Parameters!$B$1) -> 250446 | P62: =IF(OR(G62="",O62=""),"",G62+O62) -> 1210986
A63: Jeonju University | B63: Counseling Psychology | C63: No | D63: Yes | E63: Masters | F63: 4574000 | G63: =IF(F63="","",F63*Parameters!$B$1) -> 960540 | H63: 1890000 | I63: =IF(H63="","",H63*Parameters!$B$1) -> 396900 | J63: =IF(OR(G63="",I63=""),"",G63+I63) -> 1357440 | K63: 1252000 | L63: =IF(K63="","",K63*Parameters!$B$1) -> 262920 | M63: =IF(OR(G63="",L63=""),"",G63+L63) -> 1223460 | N63: 1192600 | O63: =IF(N63="","",N63*Parameters!$B$1) -> 250446 | P63: =IF(OR(G63="",O63=""),"",G63+O63) -> 1210986
A64: Jeonju University | B64: Child and Special Education | C64: No | D64: Yes | E64: Masters | F64: 4574000 | G64: =IF(F64="","",F64*Parameters!$B$1) -> 960540 | H64: 1890000 | I64: =IF(H64="","",H64*Parameters!$B$1) -> 396900 | J64: =IF(OR(G64="",I64=""),"",G64+I64) -> 1357440 | K64: 1252000 | L64: =IF(K64="","",K64*Parameters!$B$1) -> 262920 | M64: =IF(OR(G64="",L64=""),"",G64+L64) -> 1223460 | N64: 1192600 | O64: =IF(N64="","",N64*Parameters!$B$1) -> 250446 | P64: =IF(OR(G64="",O64=""),"",G64+O64) -> 1210986
... A81: Jeonju University | B81: Taekwondo | C81: No | D81: Yes | E81: Masters | F81: 5442000 | G81: =IF(F81="","",F81*Parameters!$B$1) -> 1142820 | H81: 1890000 | I81: =IF(H81="","",H81*Parameters!$B$1) -> 396900 | J81: =IF(OR(G81="",I81=""),"",G81+I81) -> 1539720 | K81: 1252000 | L81: =IF(K81="","",K81*Parameters!$B$1) -> 262920 | M81: =IF(OR(G81="",L81=""),"",G81+L81) -> 1405740 | N81: 1192600 | O81: =IF(N81="","",N81*Parameters!$B$1) -> 250446 | P81: =IF(OR(G81="",O81=""),"",G81+O81) -> 1393266
A82: PhD | E82: ADMISSION FEE | F82: 650000 | G82: =IF(F82="","",F82*Parameters!$B$1) -> 136500 | J82: =IF(OR(G82="",I82=""),"",G82+I82) | L82: =IF(K82="","",K82*Parameters!$B$1) | M82: =IF(OR(G82="",L82=""),"",G82+L82) | P82: =IF(OR(G82="",O82=""),"",G82+O82)
A83: Jeonju University | B83: Business Administration | C83: No | D83: Yes | E83: PhD | F83: 4775000 | G83: =IF(F83="","",F83*Parameters!$B$1) -> 1002750 | H83: 1890000 | I83: =IF(H83="","",H83*Parameters!$B$1) -> 396900 | J83: =IF(OR(G83="",I83=""),"",G83+I83) -> 1399650 | K83: 1252000 | L83: =IF(K83="","",K83*Parameters!$B$1) -> 262920 | M83: =IF(OR(G83="",L83=""),"",G83+L83) -> 1265670 | N83: 1192600 | O83: =IF(N83="","",N83*Parameters!$B$1) -> 250446 | P83: =IF(OR(G83="",O83=""),"",G83+O83) -> 1253196
A84: Jeonju University | B84: Tourism Management | C84: No | D84: Yes | E84: PhD | F84: 4775000 | G84: =IF(F84="","",F84*Parameters!$B$1) -> 1002750 | H84: 1890000 | I84: =IF(H84="","",H84*Parameters!$B$1) -> 396900 | J84: =IF(OR(G84="",I84=""),"",G84+I84) -> 1399650 | K84: 1252000 | L84: =IF(K84="","",K84*Parameters!$B$1) -> 262920 | M84: =IF(OR(G84="",L84=""),"",G84+L84) -> 1265670 | N84: 1192600 | O84: =IF(N84="","",N84*Parameters!$B$1) -> 250446 | P84: =IF(OR(G84="",O84=""),"",G84+O84) -> 1253196
A85: Jeonju University | B85: Education | C85: No | D85: Yes | E85: PhD | F85: 4775000 | G85: =IF(F85="","",F85*Parameters!$B$1) -> 1002750 | H85: 1890000 | I85: =IF(H85="","",H85*Parameters!$B$1) -> 396900 | J85: =IF(OR(G85="",I85=""),"",G85+I85) -> 1399650 | K85: 1252000 | L85: =IF(K85="","",K85*Parameters!$B$1) -> 262920 | M85: =IF(OR(G85="",L85=""),"",G85+L85) -> 1265670 | N85: 1192600 | O85: =IF(N85="","",N85*Parameters!$B$1) -> 250446 | P85: =IF(OR(G85="",O85=""),"",G85+O85) -> 1253196
A86: Jeonju University | B86: Korean Language and Literature | C86: No | D86: Yes | E86: PhD | F86: 4775000 | G86: =IF(F86="","",F86*Parameters!$B$1) -> 1002750 | H86: 1890000 | I86: =IF(H86="","",H86*Parameters!$B$1) -> 396900 | J86: =IF(OR(G86="",I86=""),"",G86+I86) -> 1399650 | K86: 1252000 | L86: =IF(K86="","",K86*Parameters!$B$1) -> 262920 | M86: =IF(OR(G86="",L86=""),"",G86+L86) -> 1265670 | N86: 1192600 | O86: =IF(N86="","",N86*Parameters!$B$1) -> 250446 | P86: =IF(OR(G86="",O86=""),"",G86+O86) -> 1253196
A87: Jeonju University | B87: Finance and Insurance | C87: No | D87: Yes | E87: PhD | F87: 4775000 | G87: =IF(F87="","",F87*Parameters!$B$1) -> 1002750 | H87: 1890000 | I87: =IF(H87="","",H87*Parameters!$B$1) -> 396900 | J87: =IF(OR(G87="",I87=""),"",G87+I87) -> 1399650 | K87: 1252000 | L87: =IF(K87="","",K87*Parameters!$B$1) -> 262920 | M87: =IF(OR(G87="",L87=""),"",G87+L87) -> 1265670 | N87: 1192600 | O87: =IF(N87="","",N87*Parameters!$B$1) -> 250446 | P87: =IF(OR(G87="",O87=""),"",G87+O87) -> 1253196
A88: Jeonju University | B88: Public Policy | C88: No | D88: Yes | E88: PhD | F88: 4775000 | G88: =IF(F88="","",F88*Parameters!$B$1) -> 1002750 | H88: 1890000 | I88: =IF(H88="","",H88*Parameters!$B$1) -> 396900 | J88: =IF(OR(G88="",I88=""),"",G88+I88) -> 1399650 | K88: 1252000 | L88: =IF(K88="","",K88*Parameters!$B$1) -> 262920 | M88: =IF(OR(G88="",L88=""),"",G88+L88) -> 1265670 | N88: 1192600 | O88: =IF(N88="","",N88*Parameters!$B$1) -> 250446 | P88: =IF(OR(G88="",O88=""),"",G88+O88) -> 1253196
A89: Jeonju University | B89: Real Estate Studies | C89: No | D89: Yes | E89: PhD | F89: 4775000 | G89: =IF(F89="","",F89*Parameters!$B$1) -> 1002750 | H89: 1890000 | I89: =IF(H89="","",H89*Parameters!$B$1) -> 396900 | J89: =IF(OR(G89="",I89=""),"",G89+I89) -> 1399650 | K89: 1252000 | L89: =IF(K89="","",K89*Parameters!$B$1) -> 262920 | M89: =IF(OR(G89="",L89=""),"",G89+L89) -> 1265670 | N89: 1192600 | O89: =IF(N89="","",N89*Parameters!$B$1) -> 250446 | P89: =IF(OR(G89="",O89=""),"",G89+O89) -> 1253196
A90: Jeonju University | B90: Private History | C90: No | D90: Yes | E90: PhD | F90: 4775000 | G90: =IF(F90="","",F90*Parameters!$B$1) -> 1002750 | H90: 1890000 | I90: =IF(H90="","",H90*Parameters!$B$1) -> 396900 | J90: =IF(OR(G90="",I90=""),"",G90+I90) -> 1399650 | K90: 1252000 | L90: =IF(K90="","",K90*Parameters!$B$1) -> 262920 | M90: =IF(OR(G90="",L90=""),"",G90+L90) -> 1265670 | N90: 1192600 | O90: =IF(N90="","",N90*Parameters!$B$1) -> 250446 | P90: =IF(OR(G90="",O90=""),"",G90+O90) -> 1253196
A91: Jeonju University | B91: Counseling Psychology | C91: No | D91: Yes | E91: PhD | F91: 4775000 | G91: =IF(F91="","",F91*Parameters!$B$1) -> 1002750 | H91: 1890000 | I91: =IF(H91="","",H91*Parameters!$B$1) -> 396900 | J91: =IF(OR(G91="",I91=""),"",G91+I91) -> 1399650 | K91: 1252000 | L91: =IF(K91="","",K91*Parameters!$B$1) -> 262920 | M91: =IF(OR(G91="",L91=""),"",G91+L91) -> 1265670 | N91: 1192600 | O91: =IF(N91="","",N91*Parameters!$B$1) -> 250446 | P91: =IF(OR(G91="",O91=""),"",G91+O91) -> 1253196
A92: Jeonju University | B92: Theology | C92: No | D92: Yes | E92: PhD | F92: 4775000 | G92: =IF(F92="","",F92*Parameters!$B$1) -> 1002750 | H92: 1890000 | I92: =IF(H92="","",H92*Parameters!$B$1) -> 396900 | J92: =IF(OR(G92="",I92=""),"",G92+I92) -> 1399650 | K92: 1252000 | L92: =IF(K92="","",K92*Parameters!$B$1) -> 262920 | M92: =IF(OR(G92="",L92=""),"",G92+L92) -> 1265670 | N92: 1192600 | O92: =IF(N92="","",N92*Parameters!$B$1) -> 250446 | P92: =IF(OR(G92="",O92=""),"",G92+O92) -> 1253196
A93: Jeonju University | B93: Child and Special Education | C93: No | D93: Yes | E93: PhD | F93: 4775000 | G93: =IF(F93="","",F93*Parameters!$B$1) -> 1002750 | H93: 1890000 | I93: =IF(H93="","",H93*Parameters!$B$1) -> 396900 | J93: =IF(OR(G93="",I93=""),"",G93+I93) -> 1399650 | K93: 1252000 | L93: =IF(K93="","",K93*Parameters!$B$1) -> 262920 | M93: =IF(OR(G93="",L93=""),"",G93+L93) -> 1265670 | N93: 1192600 | O93: =IF(N93="","",N93*Parameters!$B$1) -> 250446 | P93: =IF(OR(G93="",O93=""),"",G93+O93) -> 1253196
...

Sheet Hannam university (Daejon)
A1: University | B1: Major | C1: English Medium | D1: Korean Medium | E1: Degree Type | F1: Tuition Fee (KRW) | G1: Tuition Fee (LKR) | H1: Dorm Option 1 (USD approx) | I1: Dorm Option 1 (LKR approx) | J1: Total with Dorm Option 1 (LKR approx) | K1: Dorm Option 2 (USD approx) | L1: Dorm Option 2 (LKR approx) | M1: Total with Dorm Option 2 (LKR approx) | N1: Dorm Option 3 (USD approx) | O1: Dorm Option 3 (LKR approx) | P1: Total with Dorm Option 3 (LKR approx) | Q1: Dorm Option 4 (USD approx) | R1: Dorm Option 4 (LKR approx) | S1: Total with Dorm Option 4 (LKR approx) | T1: Dorm Option 5 (USD approx) | U1: Dorm Option 5 (LKR approx) | V1: Total with Dorm Option 5 (LKR approx)
A2: Hannam University | B2: Department of Korean Language & Literature/Literary Creative Writing | C2: No | D2: Yes | E2: Bachelor | F2: 3545580 | G2: =IF(F2="","",F2*Parameters!$B$1) -> 744571.8 | H2: 1000 | I2: =IF(H2="","",H2*Parameters!$B$2) -> 320000 | J2: =IF(OR(G2="",I2=""),"",G2+I2) -> 1064571.8 | K2: 450 | L2: =IF(K2="","",K2*Parameters!$B$2) -> 144000 | M2: =IF(OR(G2="",L2=""),"",G2+L2) -> 888571.8 | N2: 520 | O2: =IF(N2="","",N2*Parameters!$B$2) -> 166400 | P2: =IF(OR(G2="",O2=""),"",G2+O2) -> 910971.8
A3: Hannam University | B3: Department of English Language & Literature | C3: No | D3: Yes | E3: Bachelor | F3: 3545580 | G3: =IF(F3="","",F3*Parameters!$B$1) -> 744571.8 | H3: 1000 | I3: =IF(H3="","",H3*Parameters!$B$2) -> 320000 | J3: =IF(OR(G3="",I3=""),"",G3+I3) -> 1064571.8 | K3: 450 | L3: =IF(K3="","",K3*Parameters!$B$2) -> 144000 | M3: =IF(OR(G3="",L3=""),"",G3+L3) -> 888571.8 | N3: 520 | O3: =IF(N3="","",N3*Parameters!$B$2) -> 166400 | P3: =IF(OR(G3="",O3=""),"",G3+O3) -> 910971.8
A4: Hannam University | B4: Department of Applied English Contents | C4: No | D4: Yes | E4: Bachelor | F4: 3545580 | G4: =IF(F4="","",F4*Parameters!$B$1) -> 744571.8 | H4: 1000 | I4: =IF(H4="","",H4*Parameters!$B$2) -> 320000 | J4: =IF(OR(G4="",I4=""),"",G4+I4) -> 1064571.8 | K4: 450 | L4: =IF(K4="","",K4*Parameters!$B$2) -> 144000 | M4: =IF(OR(G4="",L4=""),"",G4+L4) -> 888571.8 | N4: 520 | O4: =IF(N4="","",N4*Parameters!$B$2) -> 166400 | P4: =IF(OR(G4="",O4=""),"",G4+O4) -> 910971.8
A5: Hannam University | B5: Japanese Language & Literature | C5: Yes | D5: No | E5: Bachelor | F5: 3545580 | G5: =IF(F5="","",F5*Parameters!$B$1) -> 744571.8 | H5: 1000 | I5: =IF(H5="","",H5*Parameters!$B$2) -> 320000 | J5: =IF(OR(G5="",I5=""),"",G5+I5) -> 1064571.8 | K5: 450 | L5: =IF(K5="","",K5*Parameters!$B$2) -> 144000 | M5: =IF(OR(G5="",L5=""),"",G5+L5) -> 888571.8 | N5: 520 | O5: =IF(N5="","",N5*Parameters!$B$2) -> 166400 | P5: =IF(OR(G5="",O5=""),"",G5+O5) -> 910971.8
A6: Hannam University | B6: French Language & Literature | C6: Yes | D6: No | E6: Bachelor | F6: 3545580 | G6: =IF(F6="","",F6*Parameters!$B$1) -> 744571.8 | H6: 1000 | I6: =IF(H6="","",H6*Parameters!$B$2) -> 320000 | J6: =IF(OR(G6="",I6=""),"",G6+I6) -> 1064571.8 | K6: 450 | L6: =IF(K6="","",K6*Parameters!$B$2) -> 144000 | M6: =IF(OR(G6="",L6=""),"",G6+L6) -> 888571.8 | N6: 520 | O6: =IF(N6="","",N6*Parameters!$B$2) -> 166400 | P6: =IF(OR(G6="",O6=""),"",G6+O6) -> 910971.8
A7: Hannam University | B7: Department of Library & Information Science | C7: No | D7: Yes | E7: Bachelor | F7: 3545580 | G7: =IF(F7="","",F7*Parameters!$B$1) -> 744571.8 | H7: 1000 | I7: =IF(H7="","",H7*Parameters!$B$2) -> 320000 | J7: =IF(OR(G7="",I7=""),"",G7+I7) -> 1064571.8 | K7: 450 | L7: =IF(K7="","",K7*Parameters!$B$2) -> 144000 | M7: =IF(OR(G7="",L7=""),"",G7+L7) -> 888571.8 | N7: 520 | O7: =IF(N7="","",N7*Parameters!$B$2) -> 166400 | P7: =IF(OR(G7="",O7=""),"",G7+O7) -> 910971.8
A8: Hannam University | B8: Department of History | C8: No | D8: Yes | E8: Bachelor | F8: 3545580 | G8: =IF(F8="","",F8*Parameters!$B$1) -> 744571.8 | H8: 1000 | I8: =IF(H8="","",H8*Parameters!$B$2) -> 320000 | J8: =IF(OR(G8="",I8=""),"",G8+I8) -> 1064571.8 | K8: 450 | L8: =IF(K8="","",K8*Parameters!$B$2) -> 144000 | M8: =IF(OR(G8="",L8=""),"",G8+L8) -> 888571.8 | N8: 520 | O8: =IF(N8="","",N8*Parameters!$B$2) -> 166400 | P8: =IF(OR(G8="",O8=""),"",G8+O8) -> 910971.8
A9: Hannam University | B9: Department of Christian Studies | C9: No | D9: Yes | E9: Bachelor | F9: 3545580 | G9: =IF(F9="","",F9*Parameters!$B$1) -> 744571.8 | H9: 1000 | I9: =IF(H9="","",H9*Parameters!$B$2) -> 320000 | J9: =IF(OR(G9="",I9=""),"",G9+I9) -> 1064571.8 | K9: 450 | L9: =IF(K9="","",K9*Parameters!$B$2) -> 144000 | M9: =IF(OR(G9="",L9=""),"",G9+L9) -> 888571.8 | N9: 520 | O9: =IF(N9="","",N9*Parameters!$B$2) -> 166400 | P9: =IF(OR(G9="",O9=""),"",G9+O9) -> 910971.8
A10: Hannam University | B10: Department of Information and Communication Engineering | C10: No | D10: Yes | E10: Bachelor | F10: 4530060 | G10: =IF(F10="","",F10*Parameters!$B$1) -> 951312.6 | H10: 1000 | I10: =IF(H10="","",H10*Parameters!$B$2) -> 320000 | J10: =IF(OR(G10="",I10=""),"",G10+I10) -> 1271312.6 | K10: 450 | L10: =IF(K10="","",K10*Parameters!$B$2) -> 144000 | M10: =IF(OR(G10="",L10=""),"",G10+L10) -> 1095312.6 | N10: 520 | O10: =IF(N10="","",N10*Parameters!$B$2) -> 166400 | P10: =IF(OR(G10="",O10=""),"",G10+O10) -> 1117712.6
A11: Hannam University | B11: Department of Electrical and Electronic Engineering | C11: No | D11: Yes | E11: Bachelor | F11: 4530060 | G11: =IF(F11="","",F11*Parameters!$B$1) -> 951312.6 | H11: 1000 | I11: =IF(H11="","",H11*Parameters!$B$2) -> 320000 | J11: =IF(OR(G11="",I11=""),"",G11+I11) -> 1271312.6 | K11: 450 | L11: =IF(K11="","",K11*Parameters!$B$2) -> 144000 | M11: =IF(OR(G11="",L11=""),"",G11+L11) -> 1095312.6 | N11: 520 | O11: =IF(N11="","",N11*Parameters!$B$2) -> 166400 | P11: =IF(OR(G11="",O11=""),"",G11+O11) -> 1117712.6
